try {
	console.log('\nInside the Try');
} catch (err) {
	console.log('We have an error!');
	console.log(err);
}
console.log('Completed\n');
